(venv) obtv-admin@cdn-monitor:/opt/cdnmonitor$ nano .env
(venv) obtv-admin@cdn-monitor:/opt/cdnmonitor$ source venv/bin/activate
(venv) obtv-admin@cdn-monitor:/opt/cdnmonitor$ python3 -c "
from app import app, db
with app.app_context():
    db.create_all()
    print('Database tables created successfully')
"
DEBUG:tzlocal:/etc/timezone found, contents:
 Etc/UTC

DEBUG:tzlocal:/etc/localtime found
DEBUG:tzlocal:2 found:
 {'/etc/timezone': 'Etc/UTC', '/etc/localtime is a symlink to': 'Etc/UTC'}
INFO:apscheduler.scheduler:Scheduler started
DEBUG:apscheduler.scheduler:Looking for jobs to run
DEBUG:apscheduler.scheduler:No jobs; waiting until a job is added
Traceback (most recent call last):
  File "/opt/cdnmonitor/venv/lib/python3.10/site-packages/sqlalchemy/engine/base.py", line 145, in __init__
    self._dbapi_connection = engine.raw_connection()
  File "/opt/cdnmonitor/venv/lib/python3.10/site-packages/sqlalchemy/engine/base.py", line 3292, in raw_connection
    return self.pool.connect()
  File "/opt/cdnmonitor/venv/lib/python3.10/site-packages/sqlalchemy/pool/base.py", line 452, in connect
    return _ConnectionFairy._checkout(self)
  File "/opt/cdnmonitor/venv/lib/python3.10/site-packages/sqlalchemy/pool/base.py", line 1269, in _checkout
    fairy = _ConnectionRecord.checkout(pool)
  File "/opt/cdnmonitor/venv/lib/python3.10/site-packages/sqlalchemy/pool/base.py", line 716, in checkout
    rec = pool._do_get()
  File "/opt/cdnmonitor/venv/lib/python3.10/site-packages/sqlalchemy/pool/impl.py", line 169, in _do_get
    with util.safe_reraise():
  File "/opt/cdnmonitor/venv/lib/python3.10/site-packages/sqlalchemy/util/langhelpers.py", line 146, in __exit__
    raise exc_value.with_traceback(exc_tb)
  File "/opt/cdnmonitor/venv/lib/python3.10/site-packages/sqlalchemy/pool/impl.py", line 167, in _do_get
    return self._create_connection()
  File "/opt/cdnmonitor/venv/lib/python3.10/site-packages/sqlalchemy/pool/base.py", line 393, in _create_connection
    return _ConnectionRecord(self)
  File "/opt/cdnmonitor/venv/lib/python3.10/site-packages/sqlalchemy/pool/base.py", line 678, in __init__
    self.__connect()
  File "/opt/cdnmonitor/venv/lib/python3.10/site-packages/sqlalchemy/pool/base.py", line 902, in __connect
    with util.safe_reraise():
  File "/opt/cdnmonitor/venv/lib/python3.10/site-packages/sqlalchemy/util/langhelpers.py", line 146, in __exit__
    raise exc_value.with_traceback(exc_tb)
  File "/opt/cdnmonitor/venv/lib/python3.10/site-packages/sqlalchemy/pool/base.py", line 898, in __connect
    self.dbapi_connection = connection = pool._invoke_creator(self)
  File "/opt/cdnmonitor/venv/lib/python3.10/site-packages/sqlalchemy/engine/create.py", line 637, in connect
    return dialect.connect(*cargs, **cparams)
  File "/opt/cdnmonitor/venv/lib/python3.10/site-packages/sqlalchemy/engine/default.py", line 616, in connect
    return self.loaded_dbapi.connect(*cargs, **cparams)
  File "/opt/cdnmonitor/venv/lib/python3.10/site-packages/psycopg2/__init__.py", line 122, in connect
    conn = _connect(dsn, connection_factory=connection_factory, **kwasync)
psycopg2.OperationalError: connection to server at "localhost" (127.0.0.1), port 5432 failed: FATAL:  password authentication failed for user "user"
connection to server at "localhost" (127.0.0.1), port 5432 failed: FATAL:  password authentication failed for user "user"


The above exception was the direct cause of the following exception:

Traceback (most recent call last):
  File "<string>", line 2, in <module>
  File "/opt/cdnmonitor/app.py", line 41, in <module>
    db.create_all()
  File "/opt/cdnmonitor/venv/lib/python3.10/site-packages/flask_sqlalchemy/extension.py", line 900, in create_all
    self._call_for_binds(bind_key, "create_all")
  File "/opt/cdnmonitor/venv/lib/python3.10/site-packages/flask_sqlalchemy/extension.py", line 881, in _call_for_binds
    getattr(metadata, op_name)(bind=engine)
  File "/opt/cdnmonitor/venv/lib/python3.10/site-packages/sqlalchemy/sql/schema.py", line 5828, in create_all
    bind._run_ddl_visitor(
  File "/opt/cdnmonitor/venv/lib/python3.10/site-packages/sqlalchemy/engine/base.py", line 3242, in _run_ddl_visitor
    with self.begin() as conn:
  File "/usr/lib/python3.10/contextlib.py", line 135, in __enter__
    return next(self.gen)
  File "/opt/cdnmonitor/venv/lib/python3.10/site-packages/sqlalchemy/engine/base.py", line 3232, in begin
    with self.connect() as conn:
  File "/opt/cdnmonitor/venv/lib/python3.10/site-packages/sqlalchemy/engine/base.py", line 3268, in connect
    return self._connection_cls(self)
  File "/opt/cdnmonitor/venv/lib/python3.10/site-packages/sqlalchemy/engine/base.py", line 147, in __init__
    Connection._handle_dbapi_exception_noconnection(
  File "/opt/cdnmonitor/venv/lib/python3.10/site-packages/sqlalchemy/engine/base.py", line 2430, in _handle_dbapi_exception_noconnection
    raise sqlalchemy_exception.with_traceback(exc_info[2]) from e
  File "/opt/cdnmonitor/venv/lib/python3.10/site-packages/sqlalchemy/engine/base.py", line 145, in __init__
    self._dbapi_connection = engine.raw_connection()
  File "/opt/cdnmonitor/venv/lib/python3.10/site-packages/sqlalchemy/engine/base.py", line 3292, in raw_connection
    return self.pool.connect()
  File "/opt/cdnmonitor/venv/lib/python3.10/site-packages/sqlalchemy/pool/base.py", line 452, in connect
    return _ConnectionFairy._checkout(self)
  File "/opt/cdnmonitor/venv/lib/python3.10/site-packages/sqlalchemy/pool/base.py", line 1269, in _checkout
    fairy = _ConnectionRecord.checkout(pool)
  File "/opt/cdnmonitor/venv/lib/python3.10/site-packages/sqlalchemy/pool/base.py", line 716, in checkout
    rec = pool._do_get()
  File "/opt/cdnmonitor/venv/lib/python3.10/site-packages/sqlalchemy/pool/impl.py", line 169, in _do_get
    with util.safe_reraise():
  File "/opt/cdnmonitor/venv/lib/python3.10/site-packages/sqlalchemy/util/langhelpers.py", line 146, in __exit__
    raise exc_value.with_traceback(exc_tb)
  File "/opt/cdnmonitor/venv/lib/python3.10/site-packages/sqlalchemy/pool/impl.py", line 167, in _do_get
    return self._create_connection()
  File "/opt/cdnmonitor/venv/lib/python3.10/site-packages/sqlalchemy/pool/base.py", line 393, in _create_connection
    return _ConnectionRecord(self)
  File "/opt/cdnmonitor/venv/lib/python3.10/site-packages/sqlalchemy/pool/base.py", line 678, in __init__
    self.__connect()
  File "/opt/cdnmonitor/venv/lib/python3.10/site-packages/sqlalchemy/pool/base.py", line 902, in __connect
    with util.safe_reraise():
  File "/opt/cdnmonitor/venv/lib/python3.10/site-packages/sqlalchemy/util/langhelpers.py", line 146, in __exit__
    raise exc_value.with_traceback(exc_tb)
  File "/opt/cdnmonitor/venv/lib/python3.10/site-packages/sqlalchemy/pool/base.py", line 898, in __connect
    self.dbapi_connection = connection = pool._invoke_creator(self)
  File "/opt/cdnmonitor/venv/lib/python3.10/site-packages/sqlalchemy/engine/create.py", line 637, in connect
    return dialect.connect(*cargs, **cparams)
  File "/opt/cdnmonitor/venv/lib/python3.10/site-packages/sqlalchemy/engine/default.py", line 616, in connect
    return self.loaded_dbapi.connect(*cargs, **cparams)
  File "/opt/cdnmonitor/venv/lib/python3.10/site-packages/psycopg2/__init__.py", line 122, in connect
    conn = _connect(dsn, connection_factory=connection_factory, **kwasync)
sqlalchemy.exc.OperationalError: (psycopg2.OperationalError) connection to server at "localhost" (127.0.0.1), port 5432 failed: FATAL:  password authentication failed for user "user"
connection to server at "localhost" (127.0.0.1), port 5432 failed: FATAL:  password authentication failed for user "user"

(Background on this error at: https://sqlalche.me/e/20/e3q8)
INFO:apscheduler.scheduler:Scheduler has been shut down
DEBUG:apscheduler.scheduler:Looking for jobs to run
DEBUG:apscheduler.scheduler:No jobs; waiting until a job is added
(venv) obtv-admin@cdn-monitor:/opt/cdnmonitor$